Workbook
Name aporte: Ju_Invest!$E$21
Name aporte_30: Ju_Invest!$E$71
Name patrimonio: Ju_Invest!$E$24
Name patrimonio_30: Ju_Invest!$E$78
Name qtd_anos: Ju_Invest!$E$22
Name qtd_anos_30: Ju_Invest!$E$76
Name Salario: Ju_Invest!$E$15
Name Salario_30: Ju_Invest!$E$69
Name taxa_mensal: Ju_Invest!$E$23
Name taxa_mensal_30: Ju_Invest!$E$77

Sheet Ju_Invest
B14: CONFIGURAÇÕES
B15: Salário | E15: 2500
B16: Rendimento Carteira | E16: 0.008
B17: Sugestão de investimento (30%) | E17: =E15*30% -> 750
B20: INVESTIMENTO MENSAL
B21: Quanto investir por mês? | E21: 200
B22: Por quantos anos? | E22: 5
B23: Qual a taxa de rendimento mensal? | E23: 0.0109
B24: Quanto de patrimônio vai acumular? | E24: =FV(taxa_mensal,qtd_anos*12,aporte*-1) -> 16815.135
B25: Quanto vai receber de dividendo por mês? | E25: =patrimonio*E16 -> 134.52108
B28: CENÁRIOS | E28: Dividendo
A29: 2 | B29: Quanto em 2 anos? | D29: =FV(taxa_mensal,A29*12,aporte*-1) -> 5452.6507 | E29: =D29*$E$16 -> 43.621206
A30: 5 | B30: Quanto em 5 anos? | D30: =FV(taxa_mensal,A30*12,aporte*-1) -> 16815.135 | E30: =D30*$E$16 -> 134.52108
A31: 10 | B31: Quanto em 10 anos? | D31: =FV(taxa_mensal,A31*12,aporte*-1) -> 49040.077 | E31: =D31*$E$16 -> 392.32061
A32: 20 | B32: Quanto em 20 anos? | D32: =FV(taxa_mensal,A32*12,aporte*-1) -> 229148.79 | E32: =D32*$E$16 -> 1833.1903
A33: 30 | B33: Quanto em 30 anos? | D33: =FV(taxa_mensal,A33*12,aporte*-1) -> 890631.22 | E33: =D33*$E$16 -> 7125.0498
B36: PERFIL | C36: Moderado
B37: VALOR A SER INVESTIDO POR MÊS | E37: 200
B39: TIPO DE FII | D39: Percentual Sugerido | E39: Valores
B40: PAPEL | D40: =VLOOKUP($C$36&"-"&B$40,Planilha2!A2:D19,4,) -> 0.32 | E40: =$E$37*D40 -> 64
B41: TIJOLO | D41: =VLOOKUP($C$36&"-"&B$41,Planilha2!A3:D20,4,) -> 0.35 | E41: =$E$37*D41 -> 70
B42: HÍBRIDOS | D42: =VLOOKUP($C$36&"-"&B$42,Planilha2!A4:D21,4,) -> 0.08 | E42: =$E$37*D42 -> 16
B43: FOFs | D43: =VLOOKUP($C$36&"-"&B$43,Planilha2!A5:D22,4,) -> 0.05 | E43: =$E$37*D43 -> 10
B44: DESENVOLVIMENTO | D44: =VLOOKUP($C$36&"-"&B$44,Planilha2!A6:D23,4,) -> 0.1 | E44: =$E$37*D44 -> 20
B45: HOTELARIAS | D45: =VLOOKUP($C$36&"-"&B$45,Planilha2!A7:D24,4,) -> 0.1 | E45: =$E$37*D45 -> 20
E46: =SUM(E40:E45) -> 200
B68: CONFIGURAÇÕES 30% DO SALÁRIO
B69: Salário | E69: 10000
B70: Rendimento Carteira | E70: 0.007
B71: Sugestão de investimento (30%) | E71: =E69*30% -> 3000
B74: INVESTIMENTO MENSAL 30%
B75: Quanto investir por mês? | E75: =Salario_30*30% -> 3000
B76: Por quantos anos? | E76: 5
B77: Qual a taxa de rendimento mensal? | E77: 0.0105
B78: Quanto de patrimônio vai acumular? | E78: =FV(taxa_mensal_30,qtd_anos_30*12,aporte_30*-1) -> 248986.75
B79: Quanto vai receber de dividendo por mês? | E79: =patrimonio_30*E16 -> 1991.894
A82: 2 | B82: CENÁRIOS 30% | E82: Dividendo
A83: 5 | B83: Quanto em 2 anos? | D83: =FV(taxa_mensal_30,A82*12,aporte_30*-1) -> 81401.944 | E83: =D83*$E$16 -> 651.21555
A84: 10 | B84: Quanto em 5 anos? | D84: =FV(taxa_mensal_30,A83*12,aporte_30*-1) -> 248986.75 | E84: =D84*$E$16 -> 1991.894
A85: 20 | B85: Quanto em 10 anos? | D85: =FV(taxa_mensal_30,A84*12,aporte_30*-1) -> 714953.91 | E85: =D85*$E$16 -> 5719.6313
...

Sheet Planilha2
A1: CHAVE | B1: PERFIL | C1: TIPO DE FII | D1: %
A2: =B2&"-"&C2 -> Conservador-PAPEL | B2: Conservador | C2: PAPEL | D2: 0.3
A3: =B3&"-"&C3 -> Conservador-TIJOLO | B3: Conservador | C3: TIJOLO | D3: 0.5
A4: =B4&"-"&C4 -> Conservador-HÍBRIDOS | B4: Conservador | C4: HÍBRIDOS | D4: 0.1
A5: =B5&"-"&C5 -> Conservador-FOFs | B5: Conservador | C5: FOFs | D5: 0.1
A6: =B6&"-"&C6 -> Conservador-DESENVOLVIMENTO | B6: Conservador | C6: DESENVOLVIMENTO | D6: 0
A7: =B7&"-"&C7 -> Conservador-HOTELARIAS | B7: Conservador | C7: HOTELARIAS | D7: 0
A8: =B8&"-"&C8 -> Moderado-PAPEL | B8: Moderado | C8: PAPEL | D8: 0.32
A9: =B9&"-"&C9 -> Moderado-TIJOLO | B9: Moderado | C9: TIJOLO | D9: 0.35
A10: =B10&"-"&C10 -> Moderado-HÍBRIDOS | B10: Moderado | C10: HÍBRIDOS | D10: 0.08
A11: =B11&"-"&C11 -> Moderado-FOFs | B11: Moderado | C11: FOFs | D11: 0.05
A12: =B12&"-"&C12 -> Moderado-DESENVOLVIMENTO | B12: Moderado | C12: DESENVOLVIMENTO | D12: 0.1
A13: =B13&"-"&C13 -> Moderado-HOTELARIAS | B13: Moderado | C13: HOTELARIAS | D13: 0.1
... A19: =B19&"-"&C19 -> Agressivo-HOTELARIAS | B19: Agressivo | C19: HOTELARIAS | D19: 0.1
